{"name": "test_12_cases_618", "status": "broken", "statusDetails": {"message": "NameError: name 'case_name' is not defined", "trace": "@pytest.mark.regress_tap\n    def test_12_cases_618():\n>       case_name('Валидация поля \"Ед. измерения\" при создании назначения лекарственного препарата')\nE       NameError: name 'case_name' is not defined\n\nautotest\\tests\\test_TAP.py:751: NameError"}, "start": 1714130333376, "stop": 1714130333376, "uuid": "4ede2deb-4002-47fe-8f13-2a92b060f7ff", "historyId": "90378b3ff8ded0a2e4fc3ccb752fa2d1", "testCaseId": "90378b3ff8ded0a2e4fc3ccb752fa2d1", "fullName": "autotest.tests.test_TAP#test_12_cases_618", "labels": [{"name": "tag", "value": "regress_tap"}, {"name": "parentSuite", "value": "autotest.tests"}, {"name": "suite", "value": "test_TAP"}, {"name": "host", "value": "Arutyun"}, {"name": "thread", "value": "19632-MainThread"}, {"name": "framework", "value": "pytest"}, {"name": "language", "value": "cpython3"}, {"name": "package", "value": "autotest.tests.test_TAP"}]}