{"name": "test_14_cases_614", "status": "broken", "statusDetails": {"message": "NameError: name 'case_name' is not defined", "trace": "@pytest.mark.regress_tap\n    def test_14_cases_614():\n>       case_name('Валидация поля \"Кол-во на курс\" при создании назначения лекарственного препарата')\nE       NameError: name 'case_name' is not defined\n\nautotest\\tests\\test_TAP.py:918: NameError"}, "start": 1714130333502, "stop": 1714130333503, "uuid": "9aa1e73f-21d6-480d-ae98-736f6d0c302a", "historyId": "f4f3e31350239e86611b1cc79bc0e929", "testCaseId": "f4f3e31350239e86611b1cc79bc0e929", "fullName": "autotest.tests.test_TAP#test_14_cases_614", "labels": [{"name": "tag", "value": "regress_tap"}, {"name": "parentSuite", "value": "autotest.tests"}, {"name": "suite", "value": "test_TAP"}, {"name": "host", "value": "Arutyun"}, {"name": "thread", "value": "19632-MainThread"}, {"name": "framework", "value": "pytest"}, {"name": "language", "value": "cpython3"}, {"name": "package", "value": "autotest.tests.test_TAP"}]}