{"name": "test_29_cases_667", "status": "broken", "statusDetails": {"message": "NameError: name 'case_name' is not defined", "trace": "@pytest.mark.regress_tap\n    def test_29_cases_667():\n>       case_name('Создание назначения со значением поля \"Дата назначения\" равным больше текущей даты')\nE       NameError: name 'case_name' is not defined\n\nautotest\\tests\\test_TAP.py:2009: NameError"}, "start": 1714130334346, "stop": 1714130334347, "uuid": "b8a31979-da8c-41cf-ac06-6b7fe053a399", "historyId": "d7af75a8dceb70629d790f5d07bd3b47", "testCaseId": "d7af75a8dceb70629d790f5d07bd3b47", "fullName": "autotest.tests.test_TAP#test_29_cases_667", "labels": [{"name": "tag", "value": "regress_tap"}, {"name": "parentSuite", "value": "autotest.tests"}, {"name": "suite", "value": "test_TAP"}, {"name": "host", "value": "Arutyun"}, {"name": "thread", "value": "19632-MainThread"}, {"name": "framework", "value": "pytest"}, {"name": "language", "value": "cpython3"}, {"name": "package", "value": "autotest.tests.test_TAP"}]}