{"name": "test_28_cases_612", "status": "broken", "statusDetails": {"message": "NameError: name 'case_name' is not defined", "trace": "@pytest.mark.regress_tap\n    def test_28_cases_612():\n>       case_name('Валидация поля \"Путь введения\" при создании назначения лекарственного препарата')\nE       NameError: name 'case_name' is not defined\n\nautotest\\tests\\test_TAP.py:1917: NameError"}, "start": 1714130334292, "stop": 1714130334292, "uuid": "cfaed914-cbda-4289-97c4-29f74405f95b", "historyId": "095e42176ad7933dfbad44e28069923c", "testCaseId": "095e42176ad7933dfbad44e28069923c", "fullName": "autotest.tests.test_TAP#test_28_cases_612", "labels": [{"name": "tag", "value": "regress_tap"}, {"name": "parentSuite", "value": "autotest.tests"}, {"name": "suite", "value": "test_TAP"}, {"name": "host", "value": "Arutyun"}, {"name": "thread", "value": "19632-MainThread"}, {"name": "framework", "value": "pytest"}, {"name": "language", "value": "cpython3"}, {"name": "package", "value": "autotest.tests.test_TAP"}]}