{"name": "test_16_cases_617", "status": "broken", "statusDetails": {"message": "NameError: name 'case_name' is not defined", "trace": "@pytest.mark.regress_tap\n    def test_16_cases_617():\n>       case_name('Валидация поля \"Раз в день\" при создании назначения лекарственного препарата')\nE       NameError: name 'case_name' is not defined\n\nautotest\\tests\\test_TAP.py:1104: NameError"}, "start": 1714130333615, "stop": 1714130333615, "uuid": "47cb0c83-1203-4010-8e97-b71c406d9cb5", "historyId": "d7d33583d49776cad3a3b3f9a4884337", "testCaseId": "d7d33583d49776cad3a3b3f9a4884337", "fullName": "autotest.tests.test_TAP#test_16_cases_617", "labels": [{"name": "tag", "value": "regress_tap"}, {"name": "parentSuite", "value": "autotest.tests"}, {"name": "suite", "value": "test_TAP"}, {"name": "host", "value": "Arutyun"}, {"name": "thread", "value": "19632-MainThread"}, {"name": "framework", "value": "pytest"}, {"name": "language", "value": "cpython3"}, {"name": "package", "value": "autotest.tests.test_TAP"}]}