{"name": "test_25_cases_593", "status": "broken", "statusDetails": {"message": "NameError: name 'case_name' is not defined", "trace": "@pytest.mark.regress_tap\n    def test_25_cases_593():\n>       case_name('Заполнение полей рецепта. Валидация поля \"Дата выписки\"')\nE       NameError: name 'case_name' is not defined\n\nautotest\\tests\\test_TAP.py:1738: NameError"}, "start": 1714130334127, "stop": 1714130334127, "uuid": "fea9f7ea-b014-4e3a-82bd-83739c6d531e", "historyId": "9289fcbd252ded75748e5c2a037125c4", "testCaseId": "9289fcbd252ded75748e5c2a037125c4", "fullName": "autotest.tests.test_TAP#test_25_cases_593", "labels": [{"name": "tag", "value": "regress_tap"}, {"name": "parentSuite", "value": "autotest.tests"}, {"name": "suite", "value": "test_TAP"}, {"name": "host", "value": "Arutyun"}, {"name": "thread", "value": "19632-MainThread"}, {"name": "framework", "value": "pytest"}, {"name": "language", "value": "cpython3"}, {"name": "package", "value": "autotest.tests.test_TAP"}]}