{"name": "test_5_cases_595", "status": "broken", "statusDetails": {"message": "NameError: name 'case_name' is not defined", "trace": "@pytest.mark.regress_tap\n    def test_5_cases_595():\n>       case_name('Заполнение полей рецепта. Валидация поля \"Адрес доставки\"')\nE       NameError: name 'case_name' is not defined\n\nautotest\\tests\\test_TAP.py:199: NameError"}, "start": 1714130332964, "stop": 1714130332964, "uuid": "dcd7ba66-035a-464c-8564-e7f4189317cc", "historyId": "98f54df317d8b97d4d4717fff5a79358", "testCaseId": "98f54df317d8b97d4d4717fff5a79358", "fullName": "autotest.tests.test_TAP#test_5_cases_595", "labels": [{"name": "tag", "value": "regress_tap"}, {"name": "parentSuite", "value": "autotest.tests"}, {"name": "suite", "value": "test_TAP"}, {"name": "host", "value": "Arutyun"}, {"name": "thread", "value": "19632-MainThread"}, {"name": "framework", "value": "pytest"}, {"name": "language", "value": "cpython3"}, {"name": "package", "value": "autotest.tests.test_TAP"}]}