{"name": "test_10_case_616", "status": "broken", "statusDetails": {"message": "NameError: name 'case_name' is not defined", "trace": "@pytest.mark.regress_tap\n    def test_10_case_616():\n>       case_name('Валидация поля \"Дата начала\" при создании назначения лекарственного препарата')\nE       NameError: name 'case_name' is not defined\n\nautotest\\tests\\test_TAP.py:586: NameError"}, "start": 1714130333264, "stop": 1714130333264, "uuid": "d225cc4c-7220-4f68-b467-a33de6179aeb", "historyId": "4a787df080dc815ee4a0a6bf98197824", "testCaseId": "4a787df080dc815ee4a0a6bf98197824", "fullName": "autotest.tests.test_TAP#test_10_case_616", "labels": [{"name": "tag", "value": "regress_tap"}, {"name": "parentSuite", "value": "autotest.tests"}, {"name": "suite", "value": "test_TAP"}, {"name": "host", "value": "Arutyun"}, {"name": "thread", "value": "19632-MainThread"}, {"name": "framework", "value": "pytest"}, {"name": "language", "value": "cpython3"}, {"name": "package", "value": "autotest.tests.test_TAP"}]}