{"name": "test_17_cases_619", "status": "broken", "statusDetails": {"message": "NameError: name 'case_name' is not defined", "trace": "@pytest.mark.regress_tap\n    def test_17_cases_619():\n>       case_name('Валидация поля \"Разовая доза\" при создании назначения лекарственного препарата')\nE       NameError: name 'case_name' is not defined\n\nautotest\\tests\\test_TAP.py:1200: NameError"}, "start": 1714130333671, "stop": 1714130333672, "uuid": "188647f7-7e24-464f-8a4d-9ae8b267253c", "historyId": "b2e3514bcfbe5e81776deaea5001a2ec", "testCaseId": "b2e3514bcfbe5e81776deaea5001a2ec", "fullName": "autotest.tests.test_TAP#test_17_cases_619", "labels": [{"name": "tag", "value": "regress_tap"}, {"name": "parentSuite", "value": "autotest.tests"}, {"name": "suite", "value": "test_TAP"}, {"name": "host", "value": "Arutyun"}, {"name": "thread", "value": "19632-MainThread"}, {"name": "framework", "value": "pytest"}, {"name": "language", "value": "cpython3"}, {"name": "package", "value": "autotest.tests.test_TAP"}]}