{"name": "test_13_cases_615", "status": "broken", "statusDetails": {"message": "NameError: name 'case_name' is not defined", "trace": "@pytest.mark.regress_tap\n    def test_13_cases_615():\n>       case_name('Валидация поля \"Кол-во дней\" при создании назначения лекарственного препарата')\nE       NameError: name 'case_name' is not defined\n\nautotest\\tests\\test_TAP.py:849: NameError"}, "start": 1714130333441, "stop": 1714130333442, "uuid": "a6fd1084-1590-4d0c-8cb6-95d685d428f7", "historyId": "3ab0610ad58bc4ac3e593417ec35cfc1", "testCaseId": "3ab0610ad58bc4ac3e593417ec35cfc1", "fullName": "autotest.tests.test_TAP#test_13_cases_615", "labels": [{"name": "tag", "value": "regress_tap"}, {"name": "parentSuite", "value": "autotest.tests"}, {"name": "suite", "value": "test_TAP"}, {"name": "host", "value": "Arutyun"}, {"name": "thread", "value": "19632-MainThread"}, {"name": "framework", "value": "pytest"}, {"name": "language", "value": "cpython3"}, {"name": "package", "value": "autotest.tests.test_TAP"}]}