{"name": "test_9_case_609", "status": "broken", "statusDetails": {"message": "NameError: name 'case_name' is not defined", "trace": "@pytest.mark.regress_tap\n    def test_9_case_609():\n>       case_name('Валидация поля \"Врач\" при создании назначения лекарственного препарата')\nE       NameError: name 'case_name' is not defined\n\nautotest\\tests\\test_TAP.py:475: NameError"}, "start": 1714130333205, "stop": 1714130333206, "uuid": "4e5e45e0-4306-4c38-8acc-ec79ae56beb7", "historyId": "c241962996a2b4f26df0aac7b022a96d", "testCaseId": "c241962996a2b4f26df0aac7b022a96d", "fullName": "autotest.tests.test_TAP#test_9_case_609", "labels": [{"name": "tag", "value": "regress_tap"}, {"name": "parentSuite", "value": "autotest.tests"}, {"name": "suite", "value": "test_TAP"}, {"name": "host", "value": "Arutyun"}, {"name": "thread", "value": "19632-MainThread"}, {"name": "framework", "value": "pytest"}, {"name": "language", "value": "cpython3"}, {"name": "package", "value": "autotest.tests.test_TAP"}]}