{"name": "test_6_cases_14508", "status": "broken", "statusDetails": {"message": "NameError: name 'case_name' is not defined", "trace": "@pytest.mark.regress_tap\n    def test_6_cases_14508():\n>       case_name('Валидация поля \"Дата выписки\" при создании рецепта с датой больше/меньще текущей')\nE       NameError: name 'case_name' is not defined\n\nautotest\\tests\\test_TAP.py:283: NameError"}, "start": 1714130333024, "stop": 1714130333024, "uuid": "f68a1c06-4c08-4aa8-8b5a-21deeca3924f", "historyId": "eb8bacbffb44dcd5a0698ea9c2426dff", "testCaseId": "eb8bacbffb44dcd5a0698ea9c2426dff", "fullName": "autotest.tests.test_TAP#test_6_cases_14508", "labels": [{"name": "tag", "value": "regress_tap"}, {"name": "parentSuite", "value": "autotest.tests"}, {"name": "suite", "value": "test_TAP"}, {"name": "host", "value": "Arutyun"}, {"name": "thread", "value": "19632-MainThread"}, {"name": "framework", "value": "pytest"}, {"name": "language", "value": "cpython3"}, {"name": "package", "value": "autotest.tests.test_TAP"}]}