{"name": "test_24_cases_592", "status": "broken", "statusDetails": {"message": "NameError: name 'case_name' is not defined", "trace": "@pytest.mark.regress_tap\n    def test_24_cases_592():\n>       case_name('Заполнение полей рецепта. Валидация поля \"Врач\"')\nE       NameError: name 'case_name' is not defined\n\nautotest\\tests\\test_TAP.py:1655: NameError"}, "start": 1714130334068, "stop": 1714130334069, "uuid": "69b6864b-c13e-4d63-9d87-0c661ecdfebe", "historyId": "a6c4c38b1975651d122cf9fb49aa5ecc", "testCaseId": "a6c4c38b1975651d122cf9fb49aa5ecc", "fullName": "autotest.tests.test_TAP#test_24_cases_592", "labels": [{"name": "tag", "value": "regress_tap"}, {"name": "parentSuite", "value": "autotest.tests"}, {"name": "suite", "value": "test_TAP"}, {"name": "host", "value": "Arutyun"}, {"name": "thread", "value": "19632-MainThread"}, {"name": "framework", "value": "pytest"}, {"name": "language", "value": "cpython3"}, {"name": "package", "value": "autotest.tests.test_TAP"}]}