{"name": "test_18_cases_613", "status": "broken", "statusDetails": {"message": "NameError: name 'case_name' is not defined", "trace": "@pytest.mark.regress_tap\n    def test_18_cases_613():\n>       case_name('Валидация поля \"Разовая доза\" при создании назначения лекарственного препарата')\nE       NameError: name 'case_name' is not defined\n\nautotest\\tests\\test_TAP.py:1296: NameError"}, "start": 1714130333727, "stop": 1714130333727, "uuid": "098e2a09-7786-4627-8704-edd49bc78e2c", "historyId": "45f4ea04388fd5cf48391ef9a458fcf0", "testCaseId": "45f4ea04388fd5cf48391ef9a458fcf0", "fullName": "autotest.tests.test_TAP#test_18_cases_613", "labels": [{"name": "tag", "value": "regress_tap"}, {"name": "parentSuite", "value": "autotest.tests"}, {"name": "suite", "value": "test_TAP"}, {"name": "host", "value": "Arutyun"}, {"name": "thread", "value": "19632-MainThread"}, {"name": "framework", "value": "pytest"}, {"name": "language", "value": "cpython3"}, {"name": "package", "value": "autotest.tests.test_TAP"}]}