{"name": "test_15_cases_610", "status": "broken", "statusDetails": {"message": "NameError: name 'case_name' is not defined", "trace": "@pytest.mark.regress_tap\n    def test_15_cases_610():\n>       case_name('Валидация поля \"Обоснование назначения\" при создании назначения лекарственного препарата')\nE       NameError: name 'case_name' is not defined\n\nautotest\\tests\\test_TAP.py:1028: NameError"}, "start": 1714130333560, "stop": 1714130333560, "uuid": "7b10f531-a113-4174-826d-4a7ce6be368c", "historyId": "9a2db7ab160797acf10bf6b4bfc547a2", "testCaseId": "9a2db7ab160797acf10bf6b4bfc547a2", "fullName": "autotest.tests.test_TAP#test_15_cases_610", "labels": [{"name": "tag", "value": "regress_tap"}, {"name": "parentSuite", "value": "autotest.tests"}, {"name": "suite", "value": "test_TAP"}, {"name": "host", "value": "Arutyun"}, {"name": "thread", "value": "19632-MainThread"}, {"name": "framework", "value": "pytest"}, {"name": "language", "value": "cpython3"}, {"name": "package", "value": "autotest.tests.test_TAP"}]}